<?xml version="1.0" ?>
<robot name="ecm" xmlns:xacro="http://www.ros.org/wiki/xacro">
  <!-- Colors -->
  <xacro:include filename="$(find dvrk_model)/urdf/common.urdf.xacro"/>

  <!-- Macro for da Vinci Endoscope Camera Manipulator (ECM) -->
  <xacro:macro name="ecm_base" params="prefix parent_link xyz:='0.0 0.0 0.0' rpy:='0.0 0.0 0.0'">

    <!-- Joint 0: Fixed to World-->
    <joint name="fixed" type="fixed">
      <parent link="${parent_link}"/>
      <child link="${prefix}_base_link"/>
      <origin rpy="${rpy}" xyz="${xyz}"/>
    </joint>

    <link name="${prefix}_base_link"/>

    <!-- Joint 1: Outer Yaw -->
    <joint name="yaw" type="revolute">
      <parent link="${prefix}_base_link"/>
      <child link="${prefix}_yaw_link"/>
      <origin rpy="0 -${PI/2} ${PI/2}" xyz="0 0 0"/>
      <axis xyz="0 0 1"/>
      <!--rotates about z axis-->
      <!--limit effort and velocity picked arbitrarily check-->
      <limit effort="50.0" lower="${-75/180*PI}" upper="${PI/4}" velocity="2"/>
      <joint_properties damping="1.0" friction="0.0"/>
    </joint>

    <link name="${prefix}_yaw_link">
      <visual>
        <origin rpy="0 0 -${PI/2}" xyz="0 0 0.603"/>
        <geometry>
          <mesh filename="package://dvrk_model/meshes/Classic/ECM/ecm_yaw_link.stl"/>
        </geometry>
	<material name="DaVinciGreen"/>
      </visual>
      <collision>
        <origin rpy="0 0 -${PI/2}" xyz="0 0 0.603"/>
        <geometry>
          <mesh filename="package://dvrk_model/meshes/Classic/ECM/ecm_yaw_link.stl"/>
        </geometry>
      </collision>
    </link>

    <!-- Joint 2: Pitch -->
    <joint name="pitch" type="revolute">
      <parent link="${prefix}_yaw_link"/>
      <child link="${prefix}_pitch_link"/>
      <origin rpy="-${PI/2} -${PI/2} 0" xyz="0 0 0"/>
      <axis xyz="0 0 1"/>
      <limit effort="100.0" lower="${-PI/4}" upper="${PI*65/180}" velocity="10"/>
      <joint_properties damping="1.0" friction="0.0"/>
    </joint>
    <link name="${prefix}_pitch_link"/>

    <joint name="pitch_0" type="continuous">
      <parent link="${prefix}_yaw_link"/>
      <child link="${prefix}_pitch_link_1"/>
      <origin rpy="-${PI/2} -${PI/2} 0" xyz="0 0 0.378"/>
      <axis xyz="0 0 1"/>
      <joint_properties damping="1.0" friction="0.0"/>
      <mimic joint="pitch" multiplier="1"/>
    </joint>

    <link name="${prefix}_pitch_link_1">
      <visual>
        <origin rpy="0 0 0" xyz="0 0 0"/>
        <geometry>
          <mesh filename="package://dvrk_model/meshes/Classic/ECM/ecm_pitch_link_1.stl"/>
        </geometry>
	<material name="DaVinciMedGray"/>
      </visual>
      <collision>
        <origin rpy="0 0 0" xyz="0 0 0"/>
        <geometry>
          <mesh filename="package://dvrk_model/meshes/Classic/ECM/ecm_pitch_link_1.stl"/>
        </geometry>
      </collision>
      <inertial>
        <mass value=".9"/>
        <inertia ixx="9.0" ixy="0.0" ixz="0.0" iyy="9.0" iyz="0.0" izz="9.0"/>
      </inertial>
    </link>

    <joint name="pitch_1" type="continuous">
      <parent link="${prefix}_pitch_link_1"/>
      <child link="${prefix}_pitch_link_2"/>
      <origin rpy="0 0 0" xyz="0.0558629 0.274575 0"/>
      <axis xyz="0 0 1"/>
      <joint_properties damping="1.0" friction="0.0"/>
      <mimic joint="pitch" multiplier="-1"/>
    </joint>

    <link name="${prefix}_pitch_link_2">
      <visual>
        <origin rpy="0 0 0" xyz="0 0 0"/>
        <geometry>
          <mesh filename="package://dvrk_model/meshes/Classic/ECM/ecm_pitch_link_2.stl"/>
        </geometry>
	<material name="DaVinciMedGray"/>
      </visual>
      <collision>
        <origin rpy="0 0 0" xyz="0 0 0"/>
        <geometry>
          <mesh filename="package://dvrk_model/meshes/Classic/ECM/ecm_pitch_link_2.stl"/>
        </geometry>
      </collision>
      <inertial>
        <mass value=".9"/>
        <inertia ixx="9.0" ixy="0.0" ixz="0.0" iyy="9.0" iyz="0.0" izz="9.0"/>
      </inertial>
    </link>

    <joint name="pitch_2" type="continuous">
      <parent link="${prefix}_pitch_link_2"/>
      <child link="${prefix}_pitch_link_3"/>
      <origin rpy="0 0 0" xyz="-0.340 0 0"/>
      <axis xyz="0 0 1"/>
      <joint_properties damping="1.0" friction="0.0"/>
      <mimic joint="pitch" multiplier="1"/>
    </joint>

    <link name="${prefix}_pitch_link_3">
      <visual>
        <origin rpy="0 0 0" xyz="0 0 0"/>
        <geometry>
          <mesh filename="package://dvrk_model/meshes/Classic/ECM/ecm_pitch_link_3.stl"/>
        </geometry>
	<material name="DaVinciMedGray"/>
      </visual>
      <collision>
        <origin rpy="0 0 0" xyz="0 0 0"/>
        <geometry>
          <mesh filename="package://dvrk_model/meshes/Classic/ECM/ecm_pitch_link_3.stl"/>
        </geometry>
      </collision>
      <inertial>
        <mass value=".9"/>
        <inertia ixx="9.0" ixy="0.0" ixz="0.0" iyy="9.0" iyz="0.0" izz="9.0"/>
      </inertial>
    </link>

    <!-- Joint 3: Insertion -->
    <joint name="insertion" type="prismatic">
      <parent link="${prefix}_pitch_link"/>
      <child link="${prefix}_insertion_link"/>
      <origin rpy="${PI/2} 0 0" xyz="0 0.3822 0"/>
      <axis xyz="0 0 1"/>
      <joint_properties damping="1.0" friction="0.0"/>
      <limit effort="100.0" lower="0" upper="0.235" velocity="10"/>
    </joint>

    <link name="${prefix}_insertion_link">
      <visual>
        <origin rpy="0 0 0" xyz="0 0 0"/>
        <geometry>
          <mesh filename="package://dvrk_model/meshes/Classic/ECM/ecm_insertion_link.stl"/>
        </geometry>
	<material name="DaVinciBlue"/>
      </visual>
      <collision>
        <origin rpy="0 0 0" xyz="0 0 0"/>
        <geometry>
          <mesh filename="package://dvrk_model/meshes/Classic/ECM/ecm_insertion_link.stl"/>
        </geometry>
      </collision>
    </link>

    <!-- Joint 4: Roll -->
    <joint name="roll" type="revolute">
      <parent link="${prefix}_insertion_link"/>
      <child link="${prefix}_roll_link"/>
      <origin rpy="0 0 0" xyz="0 0 0.3829"/>
      <axis xyz="0 0 1"/>
      <joint_properties damping="1.0" friction="0.0"/>
      <limit effort="100.0" lower="-${PI/2}" upper="${PI/2}" velocity="10"/>
    </joint>

    <link name="${prefix}_roll_link">
      <visual>
        <origin rpy="0 0 0" xyz="0 0 0"/>
        <geometry>
          <mesh filename="package://dvrk_model/meshes/Classic/ECM/ecm_roll_link.stl"/>
        </geometry>
	<material name="DaVinciBlue"/>
      </visual>
      <collision>
        <origin rpy="0 0 0" xyz="0 0 0"/>
        <geometry>
          <mesh filename="package://dvrk_model/meshes/Classic/ECM/ecm_roll_link.stl"/>
        </geometry>
      </collision>
    </link>

  </xacro:macro>

</robot>
