<?xml version="1.0"?>

<robot name="patient_cart" xmlns:xacro="http://www.ros.org/wiki/xacro">

  <xacro:include filename="$(find dvrk_model)/urdf/common.urdf.xacro"/>

  <link name="world"/>
  <joint name="fixed" type="fixed">
    <origin
        xyz="0 0 0.167458"
        rpy="0 0 0" />
    <parent link="world"/>
    <child link="base_link"/>
  </joint>

  <link
      name="base_link">
    <visual>
      <origin
          xyz="0 0 0"
          rpy="0 0 0" />
      <geometry>
        <mesh
            filename="package://dvrk_model/meshes/Classic/SUJ/base_link.stl" />
      </geometry>
      <material
          name="">
        <color
            rgba="0.647058823529412 0.619607843137255 0.588235294117647 1" />
      </material>
    </visual>
    <collision>
      <origin
          xyz="0 0 0"
          rpy="0 0 0" />
      <geometry>
        <mesh
            filename="package://dvrk_model/meshes/Classic/SUJ/base_link.stl" />
      </geometry>
    </collision>
  </link>
  <link
      name="suj_psm2_L0">
    <visual>
      <origin
          xyz="0 0 0"
          rpy="0 0 0" />
      <geometry>
        <mesh
            filename="package://dvrk_model/meshes/Classic/SUJ/suj_psm2_L0.stl" />
      </geometry>
      <material
          name="">
        <color
            rgba="0.792156862745098 0.819607843137255 0.933333333333333 1" />
      </material>
    </visual>
    <collision>
      <origin
          xyz="0 0 0"
          rpy="0 0 0" />
      <geometry>
        <mesh
            filename="package://dvrk_model/meshes/Classic/SUJ/suj_psm2_L0.stl" />
      </geometry>
    </collision>
  </link>
  <joint
      name="SUJ_PSM2_J0"
      type="prismatic">
    <origin
        xyz="0.1912 -0.101599999999999 0.761099999999999"
        rpy="-${PI} 0.0 ${PI}" />
    <parent
        link="base_link" />
    <child
        link="suj_psm2_L0" />
    <axis
        xyz="0 0 -1" />
    <limit
        lower="-0.3798"
        upper="0.8425"
        effort="50"
        velocity="50" />
  </joint>
  <link
      name="suj_psm2_L1">
    <visual>
      <origin
          xyz="0 0 0"
          rpy="0 0 0" />
      <geometry>
        <mesh
            filename="package://dvrk_model/meshes/Classic/SUJ/suj_psm2_L1.stl" />
      </geometry>
      <material
          name="">
        <color
            rgba="0.792156862745098 0.819607843137255 0.933333333333333 1" />
      </material>
    </visual>
    <collision>
      <origin
          xyz="0 0 0"
          rpy="0 0 0" />
      <geometry>
        <mesh
            filename="package://dvrk_model/meshes/Classic/SUJ/suj_psm2_L1.stl" />
      </geometry>
    </collision>
  </link>
  <joint
      name="SUJ_PSM2_J1"
      type="continuous">
    <origin
        xyz="0 0 0"
        rpy="0 0 ${PI/2}" />
    <parent
        link="suj_psm2_L0" />
    <child
        link="suj_psm2_L1" />
    <axis
        xyz="0 0 -1" />
  </joint>
  <link
      name="suj_psm2_L2">
    <visual>
      <origin
          xyz="0 0 0"
          rpy="0 0 0" />
      <geometry>
        <mesh
            filename="package://dvrk_model/meshes/Classic/SUJ/suj_psm2_L2.stl" />
      </geometry>
      <material
          name="">
        <color
            rgba="0.792156862745098 0.819607843137255 0.933333333333333 1" />
      </material>
    </visual>
    <collision>
      <origin
          xyz="0 0 0"
          rpy="0 0 0" />
      <geometry>
        <mesh
            filename="package://dvrk_model/meshes/Classic/SUJ/suj_psm2_L2.stl" />
      </geometry>
    </collision>
  </link>
  <joint
      name="SUJ_PSM2_J2"
      type="continuous">
    <origin
        xyz="0 0.4318 -0.17125"
        rpy="${PI} 0.0 ${PI/2}" />
    <parent
        link="suj_psm2_L1" />
    <child
        link="suj_psm2_L2" />
    <axis
        xyz="0 0 1" />
  </joint>
  <link
      name="suj_psm2_L3">
    <visual>
      <origin
          xyz="0 0 0"
          rpy="0 0 0" />
      <geometry>
        <mesh
            filename="package://dvrk_model/meshes/Classic/SUJ/suj_psm2_L3.stl" />
      </geometry>
      <material
          name="">
        <color
            rgba="0.792156862745098 0.819607843137255 0.933333333333333 1" />
      </material>
    </visual>
    <collision>
      <origin
          xyz="0 0 0"
          rpy="0 0 0" />
      <geometry>
        <mesh
            filename="package://dvrk_model/meshes/Classic/SUJ/suj_psm2_L3.stl" />
      </geometry>
    </collision>
  </link>
  <joint
      name="SUJ_PSM2_J3"
      type="continuous">
    <origin
        xyz="0.4318 0 0"
        rpy="-${PI/2} 0 -${PI/2}" />
    <parent
        link="suj_psm2_L2" />
    <child
        link="suj_psm2_L3" />
    <axis
        xyz="0 -1 0" />
  </joint>
  <link
      name="suj_psm2_L4">
    <visual>
      <origin
          xyz="0 0 0"
          rpy="0 0 0" />
      <geometry>
        <mesh
            filename="package://dvrk_model/meshes/Classic/SUJ/suj_psm2_L4.stl" />
      </geometry>
      <material
          name="">
        <color
            rgba="0.792156862745098 0.819607843137255 0.933333333333333 1" />
      </material>
    </visual>
    <collision>
      <origin
          xyz="0 0 0"
          rpy="0 0 0" />
      <geometry>
        <mesh
            filename="package://dvrk_model/meshes/Classic/SUJ/suj_psm2_L4.stl" />
      </geometry>
    </collision>
  </link>
  <joint
      name="SUJ_PSM2_J4"
      type="continuous">
    <origin
        xyz="0 0.0730499999999998 0.0609999999999997"
        rpy="${PI/2} 0.0 ${PI}" />
    <parent
        link="suj_psm2_L3" />
    <child
        link="suj_psm2_L4" />
    <axis
        xyz="0 1 0" />
  </joint>

  <link name="PSM2_mounting_point"/>
  <joint
      name="PSM2_RCM"
      type="fixed">
    <origin
        xyz="0.0 0.8343 -0.04984"
        rpy="0.0 ${PI} 0.0" />
    <parent
        link="suj_psm2_L4" />
    <child
        link="PSM2_mounting_point" />
  </joint>

  <link
      name="suj_ecm_L0">
    <visual>
      <origin
          xyz="0 0 0"
          rpy="0 0 0" />
      <geometry>
        <mesh
            filename="package://dvrk_model/meshes/Classic/SUJ/suj_ecm_L0.stl" />
      </geometry>
      <material
          name="">
        <color
            rgba="0.792156862745098 0.819607843137255 0.933333333333333 1" />
      </material>
    </visual>
    <collision>
      <origin
          xyz="0 0 0"
          rpy="0 0 0" />
      <geometry>
        <mesh
            filename="package://dvrk_model/meshes/Classic/SUJ/suj_ecm_L0.stl" />
      </geometry>
    </collision>
  </link>
  <joint
      name="SUJ_ECM_J0"
      type="prismatic">
    <origin
        xyz="0 0.0896 0.7611"
        rpy="${PI} 0 -${PI/2}" />
    <parent
        link="base_link" />
    <child
        link="suj_ecm_L0" />
    <axis
        xyz="0 0 -1" />
    <limit
        lower="-0.3798"
        upper="0.8425"
        effort="50"
        velocity="50" />
  </joint>
  <link
      name="suj_ecm_L1">
    <visual>
      <origin
          xyz="0 0 0"
          rpy="0 0 0" />
      <geometry>
        <mesh
            filename="package://dvrk_model/meshes/Classic/SUJ/suj_ecm_L1.stl" />
      </geometry>
      <material
          name="">
        <color
            rgba="0.792156862745098 0.819607843137255 0.933333333333333 1" />
      </material>
    </visual>
    <collision>
      <origin
          xyz="0 0 0"
          rpy="0 0 0" />
      <geometry>
        <mesh
            filename="package://dvrk_model/meshes/Classic/SUJ/suj_ecm_L1.stl" />
      </geometry>
    </collision>
  </link>
  <joint
      name="SUJ_ECM_J1"
      type="continuous">
    <origin
        xyz="0 0 0"
        rpy="${PI} 0 ${PI/2}" />
    <parent
        link="suj_ecm_L0" />
    <child
        link="suj_ecm_L1" />
    <axis
        xyz="0 0 1" />
  </joint>
  <link
      name="suj_ecm_L2">
    <visual>
      <origin
          xyz="0 0 0"
          rpy="0 0 0" />
      <geometry>
        <mesh
            filename="package://dvrk_model/meshes/Classic/SUJ/suj_ecm_L2.stl" />
      </geometry>
      <material
          name="">
        <color
            rgba="0.792156862745098 0.819607843137255 0.933333333333333 1" />
      </material>
    </visual>
    <collision>
      <origin
          xyz="0 0 0"
          rpy="0 0 0" />
      <geometry>
        <mesh
            filename="package://dvrk_model/meshes/Classic/SUJ/suj_ecm_L2.stl" />
      </geometry>
    </collision>
  </link>
  <joint
      name="SUJ_ECM_J2"
      type="continuous">
    <origin
        xyz="0 -0.4318 0.17125"
        rpy="${PI} 0 -${PI/2}" />
    <parent
        link="suj_ecm_L1" />
    <child
        link="suj_ecm_L2" />
    <axis
        xyz="0 0 -1" />
  </joint>
  <link
      name="suj_ecm_L3">
    <visual>
      <origin
          xyz="0 0 0"
          rpy="0 0 0" />
      <geometry>
        <mesh
            filename="package://dvrk_model/meshes/Classic/SUJ/suj_ecm_L3.stl" />
      </geometry>
      <material
          name="">
        <color
            rgba="0.792156862745098 0.819607843137255 0.933333333333333 1" />
      </material>
    </visual>
    <collision>
      <origin
          xyz="0 0 0"
          rpy="0 0 0" />
      <geometry>
        <mesh
            filename="package://dvrk_model/meshes/Classic/SUJ/suj_ecm_L3.stl" />
      </geometry>
    </collision>
  </link>
  <joint
      name="SUJ_ECM_J3"
      type="continuous">
    <origin
        xyz="0.4318 0.0 0.052"
        rpy="${PI/2} 0.0 0.0" />
    <parent
        link="suj_ecm_L2" />
    <child
        link="suj_ecm_L3" />
    <axis
        xyz="0 -1 0" />
  </joint>

  <link name="ECM_mounting_point"/>
  <joint
      name="ECM_RCM"
      type="fixed">
    <origin
        xyz="-0.45788 0.55053 0.0"
        rpy="${PI/2} ${PI} -${PI/4}" />
    <parent
        link="suj_ecm_L3" />
    <child
        link="ECM_mounting_point" />
  </joint>

  <link
      name="suj_psm1_L0">
    <visual>
      <origin
          xyz="0 0 0"
          rpy="0 0 0" />
      <geometry>
        <mesh
            filename="package://dvrk_model/meshes/Classic/SUJ/suj_psm1_L0.stl" />
      </geometry>
      <material
          name="">
        <color
            rgba="0.792156862745098 0.819607843137255 0.933333333333333 1" />
      </material>
    </visual>
    <collision>
      <origin
          xyz="0 0 0"
          rpy="0 0 0" />
      <geometry>
        <mesh
            filename="package://dvrk_model/meshes/Classic/SUJ/suj_psm1_L0.stl" />
      </geometry>
    </collision>
  </link>
  <joint
      name="SUJ_PSM1_J0"
      type="prismatic">
    <origin
        xyz="-0.191199999999999 -0.1016 0.761099999999999"
        rpy="${PI} 0 0" />
    <parent
        link="base_link" />
    <child
        link="suj_psm1_L0" />
    <axis
        xyz="0 0 -1" />
    <limit
        lower="-0.3798"
        upper="0.8425"
        effort="50"
        velocity="50" />
  </joint>
  <link
      name="suj_psm1_L1">
    <visual>
      <origin
          xyz="0 0 0"
          rpy="0 0 0" />
      <geometry>
        <mesh
            filename="package://dvrk_model/meshes/Classic/SUJ/suj_psm1_L1.stl" />
      </geometry>
      <material
          name="">
        <color
            rgba="0.792156862745098 0.819607843137255 0.933333333333333 1" />
      </material>
    </visual>
    <collision>
      <origin
          xyz="0 0 0"
          rpy="0 0 0" />
      <geometry>
        <mesh
            filename="package://dvrk_model/meshes/Classic/SUJ/suj_psm1_L1.stl" />
      </geometry>
    </collision>
  </link>
  <joint
      name="SUJ_PSM1_J1"
      type="continuous">
    <origin
        xyz="0 0 0"
        rpy="0 0 ${PI/2}" />
    <parent
        link="suj_psm1_L0" />
    <child
        link="suj_psm1_L1" />
    <axis
        xyz="0 0 -1" />
  </joint>
  <link
      name="suj_psm1_L2">
    <visual>
      <origin
          xyz="0 0 0"
          rpy="0 0 0" />
      <geometry>
        <mesh
            filename="package://dvrk_model/meshes/Classic/SUJ/suj_psm1_L2.stl" />
      </geometry>
      <material
          name="">
        <color
            rgba="0.792156862745098 0.819607843137255 0.933333333333333 1" />
      </material>
    </visual>
    <collision>
      <origin
          xyz="0 0 0"
          rpy="0 0 0" />
      <geometry>
        <mesh
            filename="package://dvrk_model/meshes/Classic/SUJ/suj_psm1_L2.stl" />
      </geometry>
    </collision>
  </link>
  <joint
      name="SUJ_PSM1_J2"
      type="continuous">
    <origin
        xyz="0 0.4318 -0.171250000000001"
        rpy="${PI} 0 ${PI/2}" />
    <parent
        link="suj_psm1_L1" />
    <child
        link="suj_psm1_L2" />
    <axis
        xyz="0 0 1" />
  </joint>
  <link
      name="suj_psm1_L3">
    <visual>
      <origin
          xyz="0 0 0"
          rpy="0 0 0" />
      <geometry>
        <mesh
            filename="package://dvrk_model/meshes/Classic/SUJ/suj_psm1_L3.stl" />
      </geometry>
      <material
          name="">
        <color
            rgba="0.792156862745098 0.819607843137255 0.933333333333333 1" />
      </material>
    </visual>
    <collision>
      <origin
          xyz="0 0 0"
          rpy="0 0 0" />
      <geometry>
        <mesh
            filename="package://dvrk_model/meshes/Classic/SUJ/suj_psm1_L3.stl" />
      </geometry>
    </collision>
  </link>
  <joint
      name="SUJ_PSM1_J3"
      type="continuous">
    <origin
        xyz="0.4318 0 0"
        rpy="${PI/2} 0 -${PI/2}" />
    <parent
        link="suj_psm1_L2" />
    <child
        link="suj_psm1_L3" />
    <axis
        xyz="0 1 0" />
  </joint>
  <link
      name="suj_psm1_L4">
    <visual>
      <origin
          xyz="0 0 0"
          rpy="0 0 0" />
      <geometry>
        <mesh
            filename="package://dvrk_model/meshes/Classic/SUJ/suj_psm1_L4.stl" />
      </geometry>
      <material
          name="">
        <color
            rgba="0.792156862745098 0.819607843137255 0.933333333333333 1" />
      </material>
    </visual>
    <collision>
      <origin
          xyz="0 0 0"
          rpy="0 0 0" />
      <geometry>
        <mesh
            filename="package://dvrk_model/meshes/Classic/SUJ/suj_psm1_L4.stl" />
      </geometry>
    </collision>
  </link>
  <joint
      name="SUJ_PSM1_J4"
      type="continuous">
    <origin
        xyz="0 -0.0730499999999998 -0.0609999999999999"
        rpy="-${PI/2} 0 ${PI}" />
    <parent
        link="suj_psm1_L3" />
    <child
        link="suj_psm1_L4" />
    <axis
        xyz="0 1 0" />
  </joint>

  <link name="PSM1_mounting_point"/>
  <joint
      name="PSM1_RCM"
      type="fixed">
    <origin
        xyz="0.0 0.8343 -0.04984"
        rpy="0.0 ${PI} 0.0" />
    <parent
        link="suj_psm1_L4" />
    <child
        link="PSM1_mounting_point" />
  </joint>

  <link
      name="suj_psm3_L0">
    <visual>
      <origin
          xyz="0 0 0"
          rpy="0 0 0" />
      <geometry>
        <mesh
            filename="package://dvrk_model/meshes/Classic/SUJ/suj_psm3_L0.stl" />
      </geometry>
      <material
          name="">
        <color
            rgba="0.792156862745098 0.819607843137255 0.933333333333333 1" />
      </material>
    </visual>
    <collision>
      <origin
          xyz="0 0 0"
          rpy="0 0 0" />
      <geometry>
        <mesh
            filename="package://dvrk_model/meshes/Classic/SUJ/suj_psm3_L0.stl" />
      </geometry>
    </collision>
  </link>
  <joint
      name="SUJ_PSM3_J0"
      type="prismatic">
    <origin
        xyz="0 0.0895999999999999 0.3813"
        rpy="${PI} 0 -${PI/2}" />
    <parent
        link="base_link" />
    <child
        link="suj_psm3_L0" />
    <axis
        xyz="0 0 -1" />
    <limit
        lower="0"
        upper="1.2223"
        effort="50"
        velocity="50" />
  </joint>
  <link
      name="suj_psm3_L1">
    <visual>
      <origin
          xyz="0 0 0"
          rpy="0 0 0" />
      <geometry>
        <mesh
            filename="package://dvrk_model/meshes/Classic/SUJ/suj_psm3_L1.stl" />
      </geometry>
      <material
          name="">
        <color
            rgba="0.792156862745098 0.819607843137255 0.933333333333333 1" />
      </material>
    </visual>
    <collision>
      <origin
          xyz="0 0 0"
          rpy="0 0 0" />
      <geometry>
        <mesh
            filename="package://dvrk_model/meshes/Classic/SUJ/suj_psm3_L1.stl" />
      </geometry>
    </collision>
  </link>
  <joint
      name="SUJ_PSM3_J1"
      type="continuous">
    <origin
        xyz="0 0 0"
        rpy="${PI} 0 ${PI/2}" />
    <parent
        link="suj_psm3_L0" />
    <child
        link="suj_psm3_L1" />
    <axis
        xyz="0 0 1" />
  </joint>
  <link
      name="suj_psm3_L2">
    <visual>
      <origin
          xyz="0 0 0"
          rpy="0 0 0" />
      <geometry>
        <mesh
            filename="package://dvrk_model/meshes/Classic/SUJ/suj_psm3_L2.stl" />
      </geometry>
      <material
          name="">
        <color
            rgba="0.792156862745098 0.819607843137255 0.933333333333333 1" />
      </material>
    </visual>
    <collision>
      <origin
          xyz="0 0 0"
          rpy="0 0 0" />
      <geometry>
        <mesh
            filename="package://dvrk_model/meshes/Classic/SUJ/suj_psm3_L2.stl" />
      </geometry>
    </collision>
  </link>
  <joint
      name="SUJ_PSM3_J2"
      type="continuous">
    <origin
        xyz="0 -0.5842 -0.000249999999999639"
        rpy="${PI} 0 -${PI/2}" />
    <parent
        link="suj_psm3_L1" />
    <child
        link="suj_psm3_L2" />
    <axis
        xyz="0 0 -1" />
  </joint>
  <link
      name="suj_psm3_L3">
    <visual>
      <origin
          xyz="0 0 0"
          rpy="0 0 0" />
      <geometry>
        <mesh
            filename="package://dvrk_model/meshes/Classic/SUJ/suj_psm3_L3.stl" />
      </geometry>
      <material
          name="">
        <color
            rgba="0.792156862745098 0.819607843137255 0.933333333333333 1" />
      </material>
    </visual>
    <collision>
      <origin
          xyz="0 0 0"
          rpy="0 0 0" />
      <geometry>
        <mesh
            filename="package://dvrk_model/meshes/Classic/SUJ/suj_psm3_L3.stl" />
      </geometry>
    </collision>
  </link>
  <joint
      name="SUJ_PSM3_J3"
      type="continuous">
    <origin
        xyz="0.431800000000001 0 0"
        rpy="${PI/2} 0 -${PI/2}" />
    <parent
        link="suj_psm3_L2" />
    <child
        link="suj_psm3_L3" />
    <axis
        xyz="0 -1 0" />
  </joint>
  <link
      name="suj_psm3_L4">
    <visual>
      <origin
          xyz="0 0 0"
          rpy="0 0 0" />
      <geometry>
        <mesh
            filename="package://dvrk_model/meshes/Classic/SUJ/suj_psm3_L4.stl" />
      </geometry>
      <material
          name="">
        <color
            rgba="0.792156862745098 0.819607843137255 0.933333333333333 1" />
      </material>
    </visual>
    <collision>
      <origin
          xyz="0 0 0"
          rpy="0 0 0" />
      <geometry>
        <mesh
            filename="package://dvrk_model/meshes/Classic/SUJ/suj_psm3_L4.stl" />
      </geometry>
    </collision>
  </link>
  <joint
      name="SUJ_PSM3_J4"
      type="continuous">
    <origin
        xyz="0 -0.199949999999999 -0.061"
        rpy="-${PI/2} 0 0" />
    <parent
        link="suj_psm3_L3" />
    <child
        link="suj_psm3_L4" />
    <axis
        xyz="0 1 0" />
  </joint>

  <link name="PSM3_mounting_point"/>
  <joint
      name="PSM3_RCM"
      type="fixed">
    <origin
        xyz="0.0 0.8343 -0.04984"
        rpy="0.0 ${PI} 0.0" />
    <parent
        link="suj_psm3_L4" />
    <child
        link="PSM3_mounting_point" />
  </joint>

</robot>
