<?xml version="1.0"?>
<robot name="dvrk_si" xmlns:xacro="http://www.ros.org/wiki/xacro">

    <xacro:macro name="suj" params="prefix parent_link xyz rpy">
        <xacro:if value="${prefix == 'PSM1_' or prefix == 'PSM2_'}">
            <link
                name="SUJ_${prefix}link_0">
                <visual>
                <origin
                    xyz="0.0 0.0 0.0"
                    rpy="0.0 0.0 0.0" />
                <geometry>
                    <mesh
                    filename="package://dvrk_model/meshes/Si/SUJ/PSM/12/link_0.STL" />
                </geometry>
                <material
                    name="">
                    <color
                    rgba="0.79216 0.81961 0.93333 1.0" />
                </material>
                </visual>
                <collision>
                <origin
                    xyz="0.0 0.0 0.0"
                    rpy="0.0 0.0 0.0" />
                <geometry>
                    <mesh
                    filename="package://dvrk_model/meshes/Si/SUJ/PSM/12/link_0.STL" />
                </geometry>
                </collision>
            </link>
            <joint
                name="SUJ_${prefix}J0"
                type="prismatic">
                <origin
                xyz="${xyz}"
                rpy="${rpy}" />
                <parent
                link="${parent_link}" />
                <child
                link="SUJ_${prefix}link_0" />
                <axis
                xyz="0.0 0.0 1.0" />
                <limit
                lower="0.0"
                upper="0.512"
                effort="0.0"
                velocity="0.0" />
            </joint>
            <link
                name="SUJ_${prefix}link_1">
                <visual>
                <origin
                    xyz="0.0 0.0 0.0"
                    rpy="0.0 0.0 0.0" />
                <geometry>
                    <mesh
                    filename="package://dvrk_model/meshes/Si/SUJ/PSM/12/link_1.STL" />
                </geometry>
                <material
                    name="">
                    <color
                    rgba="0.79216 0.81961 0.93333 1.0" />
                </material>
                </visual>
                <collision>
                <origin
                    xyz="0.0 0.0 0.0"
                    rpy="0.0 0.0 0.0" />
                <geometry>
                    <mesh
                    filename="package://dvrk_model/meshes/Si/SUJ/PSM/12/link_1.STL" />
                </geometry>
                </collision>
            </link>
            <joint
                name="SUJ_${prefix}J1"
                type="revolute">
                <origin
                xyz="-0.024998 0.0 0.59"
                rpy="0.0 0.0 0.0" />
                <parent
                link="SUJ_${prefix}link_0" />
                <child
                link="SUJ_${prefix}link_1" />
                <axis
                xyz="0.0 0.0 1.0" />
                <limit
                lower="-3.141"
                upper="3.141"
                effort="0.0"
                velocity="0.0" />
            </joint>
            <link
                name="SUJ_${prefix}link_2">
                <visual>
                <origin
                    xyz="0.0 0.0 0.0"
                    rpy="0.0 0.0 0.0" />
                <geometry>
                    <mesh
                    filename="package://dvrk_model/meshes/Si/SUJ/PSM/12/link_2.STL" />
                </geometry>
                <material
                    name="">
                    <color
                    rgba="0.79216 0.81961 0.93333 1.0" />
                </material>
                </visual>
                <collision>
                <origin
                    xyz="0.0 0.0 0.0"
                    rpy="0.0 0.0 0.0" />
                <geometry>
                    <mesh
                    filename="package://dvrk_model/meshes/Si/SUJ/PSM/12/link_2.STL" />
                </geometry>
                </collision>
            </link>
            <joint
                name="SUJ_${prefix}J2"
                type="revolute">
                <origin
                xyz="0.4575 0.0 0.144"
                rpy="0.0 0.0 0.0" />
                <parent
                link="SUJ_${prefix}link_1" />
                <child
                link="SUJ_${prefix}link_2" />
                <axis
                xyz="0.0 0.0 1.0" />
                <limit
                lower="-3.141"
                upper="3.141"
                effort="0.0"
                velocity="0.0" />
            </joint>
            <link
                name="SUJ_${prefix}link_3">
                <visual>
                <origin
                    xyz="0.0 0.0 0.0"
                    rpy="0.0 0.0 0.0" />
                <geometry>
                    <mesh
                    filename="package://dvrk_model/meshes/Si/SUJ/PSM/12/link_3.STL" />
                </geometry>
                <material
                    name="">
                    <color
                    rgba="0.79216 0.81961 0.93333 1.0" />
                </material>
                </visual>
                <collision>
                <origin
                    xyz="0.0 0.0 0.0"
                    rpy="0.0 0.0 0.0" />
                <geometry>
                    <mesh
                    filename="package://dvrk_model/meshes/Si/SUJ/PSM/12/link_3.STL" />
                </geometry>
                </collision>
            </link>
            <joint
                name="SUJ_${prefix}J3"
                type="revolute">
                <origin
                xyz="0.458 0.0 -0.01875"
                rpy="0.0 0.0 0.0" />
                <parent
                link="SUJ_${prefix}link_2" />
                <child
                link="SUJ_${prefix}link_3" />
                <axis
                xyz="0.0 0.0 1.0" />
                <limit
                lower="-3.141"
                upper="3.141"
                effort="0.0"
                velocity="0.0" />
            </joint>
            <link name="${prefix}mounting_point"/>
            <joint
                name="${prefix}fixed_psm"
                type="fixed">
                <origin
                xyz="0.045255 0.0 -0.045255"
                rpy="0.0 0.7854 0.0" />
                <parent
                link="SUJ_${prefix}link_3" />
                <child
                link="${prefix}mounting_point" />
            </joint>
        </xacro:if>


        <xacro:if value="${prefix == 'PSM3_'}">
             <link
                name="SUJ_${prefix}link_0">
                <visual>
                <origin
                    xyz="0.0 0.0 0.0"
                    rpy="0.0 0.0 0.0" />
                <geometry>
                    <mesh
                    filename="package://dvrk_model/meshes/Si/SUJ/PSM/3/link_0.STL" />
                </geometry>
                <material
                    name="">
                    <color
                    rgba="0.79216 0.81961 0.93333 1.0" />
                </material>
                </visual>
                <collision>
                <origin
                    xyz="0.0 0.0 0.0"
                    rpy="0.0 0.0 0.0" />
                <geometry>
                    <mesh
                    filename="package://dvrk_model/meshes/Si/SUJ/PSM/3/link_0.STL" />
                </geometry>
                </collision>
            </link>
            <joint
                name="SUJ_${prefix}J0"
                type="prismatic">
                <origin
                xyz="${xyz}"
                rpy="${rpy}" />
                <parent
                link="${parent_link}" />
                <child
                link="SUJ_${prefix}link_0" />
                <axis
                xyz="0.0 0.0 1.0" />
                <limit
                lower="0.0"
                upper="0.512"
                effort="0.0"
                velocity="0.0" />
            </joint>
            <link
                name="SUJ_${prefix}link_1">
                <visual>
                <origin
                    xyz="0.0 0.0 0.0"
                    rpy="0.0 0.0 0.0" />
                <geometry>
                    <mesh
                    filename="package://dvrk_model/meshes/Si/SUJ/PSM/3/link_1.STL" />
                </geometry>
                <material
                    name="">
                    <color
                    rgba="0.79216 0.81961 0.93333 1.0" />
                </material>
                </visual>
                <collision>
                <origin
                    xyz="0.0 0.0 0.0"
                    rpy="0.0 0.0 0.0" />
                <geometry>
                    <mesh
                    filename="package://dvrk_model/meshes/Si/SUJ/PSM/3/link_1.STL" />
                </geometry>
                </collision>
            </link>
            <joint
                name="SUJ_${prefix}J1"
                type="revolute">
                <origin
                xyz="-0.024998 0.0 0.513"
                rpy="0.0 0.0 0.0" />
                <parent
                link="SUJ_${prefix}link_0" />
                <child
                link="SUJ_${prefix}link_1" />
                <axis
                xyz="0.0 0.0 1.0" />
                <limit
                lower="-3.14"
                upper="3.14"
                effort="0.0"
                velocity="0.0" />
            </joint>
            <link
                name="SUJ_${prefix}link_2">
                <visual>
                <origin
                    xyz="0.0 0.0 0.0"
                    rpy="0.0 0.0 0.0" />
                <geometry>
                    <mesh
                    filename="package://dvrk_model/meshes/Si/SUJ/PSM/3/link_2.STL" />
                </geometry>
                <material
                    name="">
                    <color
                    rgba="0.79216 0.81961 0.93333 1.0" />
                </material>
                </visual>
                <collision>
                <origin
                    xyz="0.0 0.0 0.0"
                    rpy="0.0 0.0 0.0" />
                <geometry>
                    <mesh
                    filename="package://dvrk_model/meshes/Si/SUJ/PSM/3/link_2.STL" />
                </geometry>
                </collision>
            </link>
            <joint
                name="SUJ_${prefix}J2"
                type="revolute">
                <origin
                xyz="0.3429 0.0 -0.1942"
                rpy="${PI} 0.0 0.0" />
                <parent
                link="SUJ_${prefix}link_1" />
                <child
                link="SUJ_${prefix}link_2" />
                <axis
                xyz="0.0 0.0 -1.0" />
                <limit
                lower="-3.14"
                upper="3.14"
                effort="0.0"
                velocity="0.0" />
            </joint>
            <link
                name="SUJ_${prefix}link_3">
                <visual>
                <origin
                    xyz="0.0 0.0 0.0"
                    rpy="0.0 0.0 0.0" />
                <geometry>
                    <mesh
                    filename="package://dvrk_model/meshes/Si/SUJ/PSM/3/link_3.STL" />
                </geometry>
                <material
                    name="">
                    <color
                    rgba="0.79216 0.81961 0.93333 1.0" />
                </material>
                </visual>
                <collision>
                <origin
                    xyz="0.0 0.0 0.0"
                    rpy="0.0 0.0 0.0" />
                <geometry>
                    <mesh
                    filename="package://dvrk_model/meshes/Si/SUJ/PSM/3/link_3.STL" />
                </geometry>
                </collision>
            </link>
            <joint
                name="SUJ_${prefix}J3"
                type="revolute">
                <origin
                xyz="0.4575 0.0 -0.0722"
                rpy="${PI} 0.0 0.0" />
                <parent
                link="SUJ_${prefix}link_2" />
                <child
                link="SUJ_${prefix}link_3" />
                <axis
                xyz="0.0 0.0 1.0" />
                <limit
                lower="-3.14"
                upper="3.14"
                effort="0.0"
                velocity="0.0" />
            </joint>
            <link
                name="SUJ_${prefix}link_4">
                <visual>
                <origin
                    xyz="0.0 0.0 0.0"
                    rpy="0.0 0.0 0.0" />
                <geometry>
                    <mesh
                    filename="package://dvrk_model/meshes/Si/SUJ/PSM/3/link_4.STL" />
                </geometry>
                <material
                    name="">
                    <color
                    rgba="0.79216 0.81961 0.93333 1.0" />
                </material>
                </visual>
                <collision>
                <origin
                    xyz="0.0 0.0 0.0"
                    rpy="0.0 0.0 0.0" />
                <geometry>
                    <mesh
                    filename="package://dvrk_model/meshes/Si/SUJ/PSM/3/link_4.STL" />
                </geometry>
                </collision>
            </link>
            <joint
                name="SUJ_${prefix}J4"
                type="revolute">
                <origin
                xyz="0.458 0.0 -0.01875"
                rpy="0.0 0.0 0.0" />
                <parent
                link="SUJ_${prefix}link_3" />
                <child
                link="SUJ_${prefix}link_4" />
                <axis
                xyz="0.0 0.0 1.0" />
                <limit
                lower="-3.14"
                upper="3.14"
                effort="0.0"
                velocity="0.0" />
            </joint>
            <link name="${prefix}mounting_point"/>
            <joint
                name="${prefix}fixed_psm"
                type="fixed">
                <origin
                xyz="0.045254 0.0 -0.11671"
                rpy="0.0 0.2618 0.0" />
                <parent
                link="SUJ_${prefix}link_4" />
                <child
                link="${prefix}mounting_point" />
            </joint>
        </xacro:if>



        <xacro:if value="${prefix == 'ECM_'}">
            <link
                name="SUJ_${prefix}link_0">
                <visual>
                <origin
                    xyz="0.0 0.0 0.0"
                    rpy="0.0 0.0 0.0" />
                <geometry>
                    <mesh
                    filename="package://dvrk_model/meshes/Si/SUJ/ECM/link_0.STL" />
                </geometry>
                <material
                    name="">
                    <color
                    rgba="0.79216 0.81961 0.93333 1.0" />
                </material>
                </visual>
                <collision>
                <origin
                    xyz="0.0 0.0 0.0"
                    rpy="0.0 0.0 0.0" />
                <geometry>
                    <mesh
                    filename="package://dvrk_model/meshes/Si/SUJ/ECM/link_0.STL" />
                </geometry>
                </collision>
            </link>
            <joint
                name="SUJ_${prefix}J0"
                type="prismatic">
                <origin
                xyz="${xyz}"
                rpy="${rpy}" />
                <parent
                link="${parent_link}" />
                <child
                link="SUJ_${prefix}link_0" />
                <axis
                xyz="0.0 0.0 1.0" />
                <limit
                lower="0.0"
                upper="0.512"
                effort="0.0"
                velocity="0.0" />
            </joint>
            <link
                name="SUJ_${prefix}link_1">
                <visual>
                <origin
                    xyz="0.0 0.0 0.0"
                    rpy="0.0 0.0 0.0" />
                <geometry>
                    <mesh
                    filename="package://dvrk_model/meshes/Si/SUJ/ECM/link_1.STL" />
                </geometry>
                <material
                    name="">
                    <color
                    rgba="0.79216 0.81961 0.93333 1.0" />
                </material>
                </visual>
                <collision>
                <origin
                    xyz="0.0 0.0 0.0"
                    rpy="0.0 0.0 0.0" />
                <geometry>
                    <mesh
                    filename="package://dvrk_model/meshes/Si/SUJ/ECM/link_1.STL" />
                </geometry>
                </collision>
            </link>
            <joint
                name="SUJ_${prefix}J1"
                type="revolute">
                <origin
                xyz="-0.025 0.0 0.5232"
                rpy="0.0 0.0 0.0" />
                <parent
                link="SUJ_${prefix}link_0" />
                <child
                link="SUJ_${prefix}link_1" />
                <axis
                xyz="0.0 0.0 1.0" />
                <limit
                lower="-3.14"
                upper="3.14"
                effort="0.0"
                velocity="0.0" />
            </joint>
            <link
                name="SUJ_${prefix}link_2">
                <visual>
                <origin
                    xyz="0.0 0.0 0.0"
                    rpy="0.0 0.0 0.0" />
                <geometry>
                    <mesh
                    filename="package://dvrk_model/meshes/Si/SUJ/ECM/link_2.STL" />
                </geometry>
                <material
                    name="">
                    <color
                    rgba="0.79216 0.81961 0.93333 1.0" />
                </material>
                </visual>
                <collision>
                <origin
                    xyz="0.0 0.0 0.0"
                    rpy="0.0 0.0 0.0" />
                <geometry>
                    <mesh
                    filename="package://dvrk_model/meshes/Si/SUJ/ECM/link_2.STL" />
                </geometry>
                </collision>
            </link>
            <joint
                name="SUJ_${prefix}J2"
                type="revolute">
                <origin
                xyz="0.3302 0.0 0.1313"
                rpy="0.0 0.0 0.0" />
                <parent
                link="SUJ_${prefix}link_1" />
                <child
                link="SUJ_${prefix}link_2" />
                <axis
                xyz="0.0 0.0 1.0" />
                <limit
                lower="-3.14"
                upper="3.14"
                effort="0.0"
                velocity="0.0" />
            </joint>
            <link
                name="SUJ_${prefix}link_3">
                <visual>
                <origin
                    xyz="0.0 0.0 0.0"
                    rpy="0.0 0.0 0.0" />
                <geometry>
                    <mesh
                    filename="package://dvrk_model/meshes/Si/SUJ/ECM/link_3.STL" />
                </geometry>
                <material
                    name="">
                    <color
                    rgba="0.79216 0.81961 0.93333 1.0" />
                </material>
                </visual>
                <collision>
                <origin
                    xyz="0.0 0.0 0.0"
                    rpy="0.0 0.0 0.0" />
                <geometry>
                    <mesh
                    filename="package://dvrk_model/meshes/Si/SUJ/ECM/link_3.STL" />
                </geometry>
                </collision>
            </link>
            <joint
                name="SUJ_${prefix}J3"
                type="revolute">
                <origin
                xyz="0.3302 0.0 0.064"
                rpy="0.0 0.0 0.0" />
                <parent
                link="SUJ_${prefix}link_2" />
                <child
                link="SUJ_${prefix}link_3" />
                <axis
                xyz="0.0 0.0 1.0" />
                <limit
                lower="-3.14"
                upper="3.14"
                effort="0.0"
                velocity="0.0" />
            </joint>
            <link name="${prefix}mounting_point"/>
            <joint
                name="${prefix}fixed_psm"
                type="fixed">
                <origin
                xyz="0.12857 0.0 -0.0109"
                rpy="0.0 1.2217 0.0" />
                <parent
                link="SUJ_${prefix}link_3" />
                <child
                link="${prefix}mounting_point" />
            </joint>
        </xacro:if>
    </xacro:macro>
</robot>
