<?xml version="1.0"?>
<robot name="dvrk_si" xmlns:xacro="http://www.ros.org/wiki/xacro">

    <xacro:macro name="suj" params="prefix parent_link xyz rpy">
        <xacro:if value="${prefix == 'PSM1_' or prefix == 'PSM2_'}">
            <link
                name="SUJ_${prefix}link_0">
                <inertial>
                <origin
                    xyz="-0.042353 -4.4531E-08 0.24208"
                    rpy="0 0 0" />
                <mass
                    value="12.704" />
                <inertia
                    ixx="0.368"
                    ixy="-6.2028E-09"
                    ixz="-0.021772"
                    iyy="0.3714"
                    iyz="5.3603E-09"
                    izz="0.047463" />
                </inertial>
                <visual>
                <origin
                    xyz="0 0 0"
                    rpy="0 0 0" />
                <geometry>
                    <mesh
                    filename="package://dvrk_model/meshes/Si/SUJ/PSM/12/link_0.STL" />
                </geometry>
                <material
                    name="">
                    <color
                    rgba="0.79216 0.81961 0.93333 1" />
                </material>
                </visual>
                <collision>
                <origin
                    xyz="0 0 0"
                    rpy="0 0 0" />
                <geometry>
                    <mesh
                    filename="package://dvrk_model/meshes/Si/SUJ/PSM/12/link_0.STL" />
                </geometry>
                </collision>
            </link>
            <joint
                name="SUJ_${prefix}j0"
                type="prismatic">
                <origin
                xyz="${xyz}"
                rpy="${rpy}" />
                <parent
                link="${parent_link}" />
                <child
                link="SUJ_${prefix}link_0" />
                <axis
                xyz="0 0 1" />
                <limit
                lower="0.0"
                upper="0.512"
                effort="0"
                velocity="0" />
            </joint>
            <link
                name="SUJ_${prefix}link_1">
                <inertial>
                <origin
                    xyz="0.21712 2.5962E-08 0.072796"
                    rpy="0 0 0" />
                <mass
                    value="7.0906" />
                <inertia
                    ixx="0.015346"
                    ixy="-1.6493E-08"
                    ixz="-0.0010396"
                    iyy="0.22426"
                    iyz="8.2106E-09"
                    izz="0.2218" />
                </inertial>
                <visual>
                <origin
                    xyz="0 0 0"
                    rpy="0 0 0" />
                <geometry>
                    <mesh
                    filename="package://dvrk_model/meshes/Si/SUJ/PSM/12/link_1.STL" />
                </geometry>
                <material
                    name="">
                    <color
                    rgba="0.79216 0.81961 0.93333 1" />
                </material>
                </visual>
                <collision>
                <origin
                    xyz="0 0 0"
                    rpy="0 0 0" />
                <geometry>
                    <mesh
                    filename="package://dvrk_model/meshes/Si/SUJ/PSM/12/link_1.STL" />
                </geometry>
                </collision>
            </link>
            <joint
                name="SUJ_${prefix}j1"
                type="revolute">
                <origin
                xyz="-0.024998 0 0.59"
                rpy="0 0 0" />
                <parent
                link="SUJ_${prefix}link_0" />
                <child
                link="SUJ_${prefix}link_1" />
                <axis
                xyz="0 0 1" />
                <limit
                lower="-3.141"
                upper="3.141"
                effort="0"
                velocity="0" />
            </joint>
            <link
                name="SUJ_${prefix}link_2">
                <inertial>
                <origin
                    xyz="0.22659 -1.07E-07 0.065498"
                    rpy="0 0 0" />
                <mass
                    value="5.8282" />
                <inertia
                    ixx="0.011467"
                    ixy="-2.0133E-09"
                    ixz="0.0026277"
                    iyy="0.19305"
                    iyz="2.1385E-09"
                    izz="0.19056" />
                </inertial>
                <visual>
                <origin
                    xyz="0 0 0"
                    rpy="0 0 0" />
                <geometry>
                    <mesh
                    filename="package://dvrk_model/meshes/Si/SUJ/PSM/12/link_2.STL" />
                </geometry>
                <material
                    name="">
                    <color
                    rgba="0.79216 0.81961 0.93333 1" />
                </material>
                </visual>
                <collision>
                <origin
                    xyz="0 0 0"
                    rpy="0 0 0" />
                <geometry>
                    <mesh
                    filename="package://dvrk_model/meshes/Si/SUJ/PSM/12/link_2.STL" />
                </geometry>
                </collision>
            </link>
            <joint
                name="SUJ_${prefix}j2"
                type="revolute">
                <origin
                xyz="0.4575 0 0.144"
                rpy="0 0 0" />
                <parent
                link="SUJ_${prefix}link_1" />
                <child
                link="SUJ_${prefix}link_2" />
                <axis
                xyz="0 0 1" />
                <limit
                lower="-3.141"
                upper="3.141"
                effort="0"
                velocity="0" />
            </joint>
            <link
                name="SUJ_${prefix}link_3">
                <inertial>
                <origin
                    xyz="0.014738 8.0422E-08 -0.027873"
                    rpy="0 0 0" />
                <mass
                    value="0.5504" />
                <inertia
                    ixx="0.00064459"
                    ixy="2.3418E-09"
                    ixz="1.1203E-05"
                    iyy="0.00057105"
                    iyz="-2.8921E-09"
                    izz="0.00085397" />
                </inertial>
                <visual>
                <origin
                    xyz="0 0 0"
                    rpy="0 0 0" />
                <geometry>
                    <mesh
                    filename="package://dvrk_model/meshes/Si/SUJ/PSM/12/link_3.STL" />
                </geometry>
                <material
                    name="">
                    <color
                    rgba="0.79216 0.81961 0.93333 1" />
                </material>
                </visual>
                <collision>
                <origin
                    xyz="0 0 0"
                    rpy="0 0 0" />
                <geometry>
                    <mesh
                    filename="package://dvrk_model/meshes/Si/SUJ/PSM/12/link_3.STL" />
                </geometry>
                </collision>
            </link>
            <joint
                name="SUJ_${prefix}j3"
                type="revolute">
                <origin
                xyz="0.458 0 -0.01875"
                rpy="0 0 0" />
                <parent
                link="SUJ_${prefix}link_2" />
                <child
                link="SUJ_${prefix}link_3" />
                <axis
                xyz="0 0 -1" />
                <limit
                lower="-3.141"
                upper="3.141"
                effort="0"
                velocity="0" />
            </joint>
            <link name="${prefix}active_arm_parent"/>
            <joint
                name="${prefix}fixed_psm"
                type="fixed">
                <origin
                xyz="0.045255 0 -0.045255"
                rpy="0 0.7854 0" />
                <parent
                link="SUJ_${prefix}link_3" />
                <child
                link="${prefix}active_arm_parent" />
            </joint>
        </xacro:if>
        
        
        <xacro:if value="${prefix == 'PSM3_'}">
             <link
                name="SUJ_${prefix}link_0">
                <inertial>
                <origin
                    xyz="-0.043484 -9.4105E-09 0.22013"
                    rpy="0 0 0" />
                <mass
                    value="11.927" />
                <inertia
                    ixx="0.27621"
                    ixy="-5.0682E-09"
                    ixz="-0.016932"
                    iyy="0.27936"
                    iyz="3.4609E-09"
                    izz="0.046091" />
                </inertial>
                <visual>
                <origin
                    xyz="0 0 0"
                    rpy="0 0 0" />
                <geometry>
                    <mesh
                    filename="package://dvrk_model/meshes/Si/SUJ/PSM/3/link_0.STL" />
                </geometry>
                <material
                    name="">
                    <color
                    rgba="0.79216 0.81961 0.93333 1" />
                </material>
                </visual>
                <collision>
                <origin
                    xyz="0 0 0"
                    rpy="0 0 0" />
                <geometry>
                    <mesh
                    filename="package://dvrk_model/meshes/Si/SUJ/PSM/3/link_0.STL" />
                </geometry>
                </collision>
            </link>
            <joint
                name="SUJ_${prefix}j0"
                type="prismatic">
                <origin
                xyz="${xyz}"
                rpy="${rpy}" />
                <parent
                link="${parent_link}" />
                <child
                link="SUJ_${prefix}link_0" />
                <axis
                xyz="0 0 1" />
                <limit
                lower="0.0"
                upper="0.512"
                effort="0"
                velocity="0" />
            </joint>
            <link
                name="SUJ_${prefix}link_1">
                <inertial>
                <origin
                    xyz="0.20518 1.3159E-05 0.040755"
                    rpy="0 0 0" />
                <mass
                    value="7.8622" />
                <inertia
                    ixx="0.043421"
                    ixy="8.2624E-06"
                    ixz="0.030604"
                    iyy="0.20282"
                    iyz="-6.5783E-05"
                    izz="0.17543" />
                </inertial>
                <visual>
                <origin
                    xyz="0 0 0"
                    rpy="0 0 0" />
                <geometry>
                    <mesh
                    filename="package://dvrk_model/meshes/Si/SUJ/PSM/3/link_1.STL" />
                </geometry>
                <material
                    name="">
                    <color
                    rgba="0.79216 0.81961 0.93333 1" />
                </material>
                </visual>
                <collision>
                <origin
                    xyz="0 0 0"
                    rpy="0 0 0" />
                <geometry>
                    <mesh
                    filename="package://dvrk_model/meshes/Si/SUJ/PSM/3/link_1.STL" />
                </geometry>
                </collision>
            </link>
            <joint
                name="SUJ_${prefix}j1"
                type="revolute">
                <origin
                xyz="-0.024998 0 0.513"
                rpy="0 0 -0.23716" />
                <parent
                link="SUJ_${prefix}link_0" />
                <child
                link="SUJ_${prefix}link_1" />
                <axis
                xyz="0 0 1" />
                <limit
                lower="-3.14"
                upper="3.14"
                effort="0"
                velocity="0" />
            </joint>
            <link
                name="SUJ_${prefix}link_2">
                <inertial>
                <origin
                    xyz="0.22894 -6.2716E-08 -9.2061E-05"
                    rpy="0 0 0" />
                <mass
                    value="6.7952" />
                <inertia
                    ixx="0.01388"
                    ixy="-1.0152E-09"
                    ixz="3.4458E-05"
                    iyy="0.21125"
                    iyz="4.6007E-09"
                    izz="0.20955" />
                </inertial>
                <visual>
                <origin
                    xyz="0 0 0"
                    rpy="0 0 0" />
                <geometry>
                    <mesh
                    filename="package://dvrk_model/meshes/Si/SUJ/PSM/3/link_2.STL" />
                </geometry>
                <material
                    name="">
                    <color
                    rgba="0.79216 0.81961 0.93333 1" />
                </material>
                </visual>
                <collision>
                <origin
                    xyz="0 0 0"
                    rpy="0 0 0" />
                <geometry>
                    <mesh
                    filename="package://dvrk_model/meshes/Si/SUJ/PSM/3/link_2.STL" />
                </geometry>
                </collision>
            </link>
            <joint
                name="SUJ_${prefix}j2"
                type="revolute">
                <origin
                xyz="0.3429 0 -0.1942"
                rpy="3.1416 0 0.41417" />
                <parent
                link="SUJ_${prefix}link_1" />
                <child
                link="SUJ_${prefix}link_2" />
                <axis
                xyz="0 0 -1" />
                <limit
                lower="-3.14"
                upper="3.14"
                effort="0"
                velocity="0" />
            </joint>
            <link
                name="SUJ_${prefix}link_3">
                <inertial>
                <origin
                    xyz="0.22659 -1.07E-07 0.065498"
                    rpy="0 0 0" />
                <mass
                    value="5.8282" />
                <inertia
                    ixx="0.011467"
                    ixy="-2.0133E-09"
                    ixz="0.0026277"
                    iyy="0.19305"
                    iyz="2.1385E-09"
                    izz="0.19056" />
                </inertial>
                <visual>
                <origin
                    xyz="0 0 0"
                    rpy="0 0 0" />
                <geometry>
                    <mesh
                    filename="package://dvrk_model/meshes/Si/SUJ/PSM/3/link_3.STL" />
                </geometry>
                <material
                    name="">
                    <color
                    rgba="0.79216 0.81961 0.93333 1" />
                </material>
                </visual>
                <collision>
                <origin
                    xyz="0 0 0"
                    rpy="0 0 0" />
                <geometry>
                    <mesh
                    filename="package://dvrk_model/meshes/Si/SUJ/PSM/3/link_3.STL" />
                </geometry>
                </collision>
            </link>
            <joint
                name="SUJ_${prefix}j3"
                type="revolute">
                <origin
                xyz="0.4575 0 -0.0722"
                rpy="3.1416 0 0.17701" />
                <parent
                link="SUJ_${prefix}link_2" />
                <child
                link="SUJ_${prefix}link_3" />
                <axis
                xyz="0 0 1" />
                <limit
                lower="-3.14"
                upper="3.14"
                effort="0"
                velocity="0" />
            </joint>
            <link
                name="SUJ_${prefix}link_4">
                <inertial>
                <origin
                    xyz="0.0016923 -2.7401E-07 -0.075019"
                    rpy="0 0 0" />
                <mass
                    value="1.4719" />
                <inertia
                    ixx="0.0038726"
                    ixy="-1.914E-08"
                    ixz="4.114E-05"
                    iyy="0.0037619"
                    iyz="2.3194E-08"
                    izz="0.0023215" />
                </inertial>
                <visual>
                <origin
                    xyz="0 0 0"
                    rpy="0 0 0" />
                <geometry>
                    <mesh
                    filename="package://dvrk_model/meshes/Si/SUJ/PSM/3/link_4.STL" />
                </geometry>
                <material
                    name="">
                    <color
                    rgba="0.79216 0.81961 0.93333 1" />
                </material>
                </visual>
                <collision>
                <origin
                    xyz="0 0 0"
                    rpy="0 0 0" />
                <geometry>
                    <mesh
                    filename="package://dvrk_model/meshes/Si/SUJ/PSM/3/link_4.STL" />
                </geometry>
                </collision>
            </link>
            <joint
                name="SUJ_${prefix}j4"
                type="revolute">
                <origin
                xyz="0.458 0 -0.01875"
                rpy="0 0 0" />
                <parent
                link="SUJ_${prefix}link_3" />
                <child
                link="SUJ_${prefix}link_4" />
                <axis
                xyz="0 0 1" />
                <limit
                lower="-3.14"
                upper="3.14"
                effort="0"
                velocity="0" />
            </joint>
            <link name="${prefix}active_arm_parent"/>
            <joint
                name="${prefix}fixed_psm"
                type="fixed">
                <origin
                xyz="0.045254 0 -0.11671"
                rpy="0 0.2618 0" />
                <parent
                link="SUJ_${prefix}link_4" />
                <child
                link="${prefix}active_arm_parent" />
            </joint>
        </xacro:if>



        <xacro:if value="${prefix == 'ECM_'}">
            <link
                name="SUJ_${prefix}link_0">
                <inertial>
                <origin
                    xyz="0.0067344 -9.5093E-09 0.27368"
                    rpy="0 0 0" />
                <mass
                    value="12.071" />
                <inertia
                    ixx="0.28901"
                    ixy="-5.2165E-09"
                    ixz="-0.017716"
                    iyy="0.29221"
                    iyz="3.7314E-09"
                    izz="0.046463" />
                </inertial>
                <visual>
                <origin
                    xyz="0 0 0"
                    rpy="0 0 0" />
                <geometry>
                    <mesh
                    filename="package://dvrk_model/meshes/Si/SUJ/ECM/link_0.STL" />
                </geometry>
                <material
                    name="">
                    <color
                    rgba="0.79216 0.81961 0.93333 1" />
                </material>
                </visual>
                <collision>
                <origin
                    xyz="0 0 0"
                    rpy="0 0 0" />
                <geometry>
                    <mesh
                    filename="package://dvrk_model/meshes/Si/SUJ/ECM/link_0.STL" />
                </geometry>
                </collision>
            </link>
            <joint
                name="SUJ_${prefix}j0"
                type="prismatic">
                <origin
                xyz="${xyz}"
                rpy="${rpy}" />
                <parent
                link="${parent_link}" />
                <child
                link="SUJ_${prefix}link_0" />
                <axis
                xyz="0 0 1" />
                <limit
                lower="0.0"
                upper="0.512"
                effort="0"
                velocity="0" />
            </joint>
            <link
                name="SUJ_${prefix}link_1">
                <inertial>
                <origin
                    xyz="0.16039 -1.1995E-08 -3.0498E-05"
                    rpy="0 0 0" />
                <mass
                    value="5.4226" />
                <inertia
                    ixx="0.011352"
                    ixy="-4.3087E-09"
                    ixz="-0.00019503"
                    iyy="0.10287"
                    iyz="3.8908E-09"
                    izz="0.10144" />
                </inertial>
                <visual>
                <origin
                    xyz="0 0 0"
                    rpy="0 0 0" />
                <geometry>
                    <mesh
                    filename="package://dvrk_model/meshes/Si/SUJ/ECM/link_1.STL" />
                </geometry>
                <material
                    name="">
                    <color
                    rgba="0.79216 0.81961 0.93333 1" />
                </material>
                </visual>
                <collision>
                <origin
                    xyz="0 0 0"
                    rpy="0 0 0" />
                <geometry>
                    <mesh
                    filename="package://dvrk_model/meshes/Si/SUJ/ECM/link_1.STL" />
                </geometry>
                </collision>
            </link>
            <joint
                name="SUJ_${prefix}j1"
                type="revolute">
                <origin
                xyz="0.025 0 0.63722"
                rpy="0 0 0" />
                <parent
                link="SUJ_${prefix}link_0" />
                <child
                link="SUJ_${prefix}link_1" />
                <axis
                xyz="0 0 1" />
                <limit
                lower="-3.14"
                upper="3.14"
                effort="0"
                velocity="0" />
            </joint>
            <link
                name="SUJ_${prefix}link_2">
                <inertial>
                <origin
                    xyz="0.15682 -3.0042E-08 -0.00012776"
                    rpy="0 0 0" />
                <mass
                    value="5.1363" />
                <inertia
                    ixx="0.010318"
                    ixy="-1.6915E-09"
                    ixz="-9.5211E-05"
                    iyy="0.099144"
                    iyz="1.2049E-09"
                    izz="0.097899" />
                </inertial>
                <visual>
                <origin
                    xyz="0 0 0"
                    rpy="0 0 0" />
                <geometry>
                    <mesh
                    filename="package://dvrk_model/meshes/Si/SUJ/ECM/link_2.STL" />
                </geometry>
                <material
                    name="">
                    <color
                    rgba="0.79216 0.81961 0.93333 1" />
                </material>
                </visual>
                <collision>
                <origin
                    xyz="0 0 0"
                    rpy="0 0 0" />
                <geometry>
                    <mesh
                    filename="package://dvrk_model/meshes/Si/SUJ/ECM/link_2.STL" />
                </geometry>
                </collision>
            </link>
            <joint
                name="SUJ_${prefix}j2"
                type="revolute">
                <origin
                xyz="0.3302 0 0.1313"
                rpy="0 0 0" />
                <parent
                link="SUJ_${prefix}link_1" />
                <child
                link="SUJ_${prefix}link_2" />
                <axis
                xyz="0 0 1" />
                <limit
                lower="-3.14"
                upper="3.14"
                effort="0"
                velocity="0" />
            </joint>
            <link
                name="SUJ_${prefix}link_3">
                <inertial>
                <origin
                    xyz="0.062935 -1.674E-07 0.023444"
                    rpy="0 0 0" />
                <mass
                    value="1.3022" />
                <inertia
                    ixx="0.0015769"
                    ixy="2.2071E-08"
                    ixz="0.00025775"
                    iyy="0.0049522"
                    iyz="2.5626E-11"
                    izz="0.0056835" />
                </inertial>
                <visual>
                <origin
                    xyz="0 0 0"
                    rpy="0 0 0" />
                <geometry>
                    <mesh
                    filename="package://dvrk_model/meshes/Si/SUJ/ECM/link_3.STL" />
                </geometry>
                <material
                    name="">
                    <color
                    rgba="0.79216 0.81961 0.93333 1" />
                </material>
                </visual>
                <collision>
                <origin
                    xyz="0 0 0"
                    rpy="0 0 0" />
                <geometry>
                    <mesh
                    filename="package://dvrk_model/meshes/Si/SUJ/ECM/link_3.STL" />
                </geometry>
                </collision>
            </link>
            <joint
                name="SUJ_${prefix}j3"
                type="revolute">
                <origin
                xyz="0.3302 0 0.064"
                rpy="0 0 0" />
                <parent
                link="SUJ_${prefix}link_2" />
                <child
                link="SUJ_${prefix}link_3" />
                <axis
                xyz="0 0 1" />
                <limit
                lower="-3.14"
                upper="3.14"
                effort="0"
                velocity="0" />
            </joint>
            <link name="${prefix}active_arm_parent"/>
            <joint
                name="${prefix}fixed_psm"
                type="fixed">
                <origin
                xyz="0.12857 0 -0.0109"
                rpy="0 1.2217 0" />
                <parent
                link="SUJ_${prefix}link_3" />
                <child
                link="${prefix}active_arm_parent" />
            </joint>
        </xacro:if>
    </xacro:macro>
</robot>