<?xml version="1.0"?>
<robot name="dvrk_si" xmlns:xacro="http://www.ros.org/wiki/xacro">

    <xacro:macro name="tool" params="tool_name prefix parent_link">
        
        <xacro:if value="${tool_name == 'P420006'}">
            <link
                name="${prefix}tool_main_link">
                <inertial>
                <origin
                    xyz="0.027084 -1.8218E-18 -0.11317"
                    rpy="0 0 0" />
                <mass
                    value="0.6606" />
                <inertia
                    ixx="0.0018902"
                    ixy="6.4481E-20"
                    ixz="7.3606E-06"
                    iyy="0.0016583"
                    iyz="-1.1311E-19"
                    izz="0.00035114" />
                </inertial>
                <visual>
                <origin
                    xyz="0 0 0"
                    rpy="0 0 0" />
                <geometry>
                    <mesh
                    filename="package://dvrk_model/meshes/instruments/420006/tool_main_link.STL" />
                </geometry>
                <material
                    name="">
                    <color
                    rgba="0.79216 0.81961 0.93333 1" />
                </material>
                </visual>
                <collision>
                <origin
                    xyz="0 0 0"
                    rpy="0 0 0" />
                <geometry>
                    <mesh
                    filename="package://dvrk_model/meshes/instruments/420006/tool_main_link.STL" />
                </geometry>
                </collision>
            </link>
            <joint
                name="${prefix}outer_insertion"
                type="prismatic">
                <origin
                xyz="0 0 0"
                rpy="0 0 0" />
                <parent
                link="${parent_link}" />
                <child
                link="${prefix}tool_main_link" />
                <axis
                xyz="0 0 -1" />
                <limit
                lower="0"
                upper="0.2987"
                effort="0"
                velocity="0" />
            </joint>
            <link
                name="${prefix}tool_wrist_link">
                <inertial>
                <origin
                    xyz="8.2268E-09 -7.7996E-08 0.0036169"
                    rpy="0 0 0" />
                <mass
                    value="0.00036792" />
                <inertia
                    ixx="4.0122E-09"
                    ixy="1.7277E-12"
                    ixz="-9.3294E-14"
                    iyy="3.5889E-09"
                    iyz="2.5109E-13"
                    izz="3.3782E-09" />
                </inertial>
                <visual>
                <origin
                    xyz="0 0 0"
                    rpy="0 0 0" />
                <geometry>
                    <mesh
                    filename="package://dvrk_model/meshes/instruments/420006/tool_wrist_link.STL" />
                </geometry>
                <material
                    name="">
                    <color
                    rgba="0.79216 0.81961 0.93333 1" />
                </material>
                </visual>
                <collision>
                <origin
                    xyz="0 0 0"
                    rpy="0 0 0" />
                <geometry>
                    <mesh
                    filename="package://dvrk_model/meshes/instruments/420006/tool_wrist_link.STL" />
                </geometry>
                </collision>
            </link>
            <joint
                name="${prefix}outer_roll"
                type="revolute">
                <origin
                xyz="0.05591 0 -0.53559"
                rpy="-3.1416 0 0" />
                <parent
                link="${prefix}tool_main_link" />
                <child
                link="${prefix}tool_wrist_link" />
                <axis
                xyz="0 0 1" />
                <limit
                lower="-3.14"
                upper="3.14"
                effort="0"
                velocity="0" />
            </joint>
            <link
                name="${prefix}tool_wrist_shaft_link">
                <inertial>
                <origin
                    xyz="9.4759E-17 -1.5613E-16 -4.0735E-06"
                    rpy="0 0 0" />
                <mass
                    value="4.9567E-05" />
                <inertia
                    ixx="2.1561E-10"
                    ixy="1.9482E-12"
                    ixz="2.1209E-25"
                    iyy="5.9138E-11"
                    iyz="-3.4641E-25"
                    izz="2.1706E-10" />
                </inertial>
                <visual>
                <origin
                    xyz="0 0 0"
                    rpy="0 0 0" />
                <geometry>
                    <mesh
                    filename="package://dvrk_model/meshes/instruments/420006/tool_wrist_shaft_link.STL" />
                </geometry>
                <material
                    name="">
                    <color
                    rgba="0.79216 0.81961 0.93333 1" />
                </material>
                </visual>
                <collision>
                <origin
                    xyz="0 0 0"
                    rpy="0 0 0" />
                <geometry>
                    <mesh
                    filename="package://dvrk_model/meshes/instruments/420006/tool_wrist_shaft_link.STL" />
                </geometry>
                </collision>
            </link>
            <joint
                name="${prefix}outer_roll_shaft"
                type="fixed">
                <origin
                xyz="0 1E-05 0.009"
                rpy="0 0 0" />
                <parent
                link="${prefix}tool_wrist_link" />
                <child
                link="${prefix}tool_wrist_shaft_link" />
                <axis
                xyz="0 0 0" />
            </joint>
            <link
                name="${prefix}tool_wrist_scal_link">
                <inertial>
                <origin
                    xyz="-6.4709E-08 6.9333E-07 0.003884"
                    rpy="0 0 0" />
                <mass
                    value="0.00016398" />
                <inertia
                    ixx="1.4976E-09"
                    ixy="-9.1973E-12"
                    ixz="-3.4692E-14"
                    iyy="1.8154E-09"
                    iyz="-8.7938E-14"
                    izz="9.1518E-10" />
                </inertial>
                <visual>
                <origin
                    xyz="0 0 0"
                    rpy="0 0 0" />
                <geometry>
                    <mesh
                    filename="package://dvrk_model/meshes/instruments/420006/tool_wrist_scal_link.STL" />
                </geometry>
                <material
                    name="">
                    <color
                    rgba="0.79216 0.81961 0.93333 1" />
                </material>
                </visual>
                <collision>
                <origin
                    xyz="0 0 0"
                    rpy="0 0 0" />
                <geometry>
                    <mesh
                    filename="package://dvrk_model/meshes/instruments/420006/tool_wrist_scal_link.STL" />
                </geometry>
                </collision>
            </link>
            <joint
                name="${prefix}outer_wrist_pitch"
                type="revolute">
                <origin
                xyz="0 0 0"
                rpy="0 0 0" />
                <parent
                link="${prefix}tool_wrist_shaft_link" />
                <child
                link="${prefix}tool_wrist_scal_link" />
                <axis
                xyz="0 -1 0" />
                <limit
                lower="-3.14"
                upper="3.14"
                effort="0"
                velocity="0" />
            </joint>
            <link
                name="${prefix}tool_wrist_sca_shaft_link">
                <inertial>
                <origin
                    xyz="-5.2457E-13 8.882E-07 2.7348E-06"
                    rpy="0 0 0" />
                <mass
                    value="1.0603E-05" />
                <inertia
                    ixx="2.9821E-12"
                    ixy="3.8929E-27"
                    ixz="5.5571E-28"
                    iyy="3.33E-11"
                    iyz="3.1897E-43"
                    izz="3.33E-11" />
                </inertial>
                <visual>
                <origin
                    xyz="0 0 0"
                    rpy="0 0 0" />
                <geometry>
                    <mesh
                    filename="package://dvrk_model/meshes/instruments/420006/tool_wrist_sca_shaft_link.STL" />
                </geometry>
                <material
                    name="">
                    <color
                    rgba="0.79216 0.81961 0.93333 1" />
                </material>
                </visual>
                <collision>
                <origin
                    xyz="0 0 0"
                    rpy="0 0 0" />
                <geometry>
                    <mesh
                    filename="package://dvrk_model/meshes/instruments/420006/tool_wrist_sca_shaft_link.STL" />
                </geometry>
                </collision>
            </link>
            <joint
                name="${prefix}outer_wrist_yaw"
                type="revolute">
                <origin
                xyz="0 0 0.0086973"
                rpy="0 0 0" />
                <parent
                link="${prefix}tool_wrist_scal_link" />
                <child
                link="${prefix}tool_wrist_sca_shaft_link" />
                <axis
                xyz="1 0 0" />
                <limit
                lower="-3.14"
                upper="3.14"
                effort="0"
                velocity="0" />
            </joint>
            <link
                name="${prefix}tool_wrist_sca_ee_link_1">
                <inertial>
                <origin
                    xyz="0.00068905 -0.00017079 0.001575"
                    rpy="0 0 0" />
                <mass
                    value="0.0002713" />
                <inertia
                    ixx="2.1945E-09"
                    ixy="-1.9034E-11"
                    ixz="2.4279E-10"
                    iyy="2.0419E-09"
                    iyz="1.3672E-10"
                    izz="4.0152E-10" />
                </inertial>
                <visual>
                <origin
                    xyz="0 0 0"
                    rpy="0 0 0" />
                <geometry>
                    <mesh
                    filename="package://dvrk_model/meshes/instruments/420006/tool_wrist_sca_ee_link_1.STL" />
                </geometry>
                <material
                    name="">
                    <color
                    rgba="0.77647 0.75686 0.73725 1" />
                </material>
                </visual>
                <collision>
                <origin
                    xyz="0 0 0"
                    rpy="0 0 0" />
                <geometry>
                    <mesh
                    filename="package://dvrk_model/meshes/instruments/420006/tool_wrist_sca_ee_link_1.STL" />
                </geometry>
                </collision>
            </link>
            <joint
                name="${prefix}jaw_1"
                type="revolute">
                <origin
                xyz="0 0 0"
                rpy="0 0 0" />
                <parent
                link="${prefix}tool_wrist_sca_shaft_link" />
                <child
                link="${prefix}tool_wrist_sca_ee_link_1" />
                <axis
                xyz="1 0 0" />
                <limit
                lower="-1.5717"
                upper="1.5717"
                effort="0"
                velocity="0" />
            </joint>
            <link
                name="${prefix}tool_wrist_sca_ee_link_2">
                <inertial>
                <origin
                    xyz="-0.00068905 0.00017079 0.001575"
                    rpy="0 0 0" />
                <mass
                    value="0.0002713" />
                <inertia
                    ixx="2.1945E-09"
                    ixy="-1.9034E-11"
                    ixz="-2.4279E-10"
                    iyy="2.0419E-09"
                    iyz="-1.3672E-10"
                    izz="4.0152E-10" />
                </inertial>
                <visual>
                <origin
                    xyz="0 0 0"
                    rpy="0 0 0" />
                <geometry>
                    <mesh
                    filename="package://dvrk_model/meshes/instruments/420006/tool_wrist_sca_ee_link_2.STL" />
                </geometry>
                <material
                    name="">
                    <color
                    rgba="0.77647 0.75686 0.73725 1" />
                </material>
                </visual>
                <collision>
                <origin
                    xyz="0 0 0"
                    rpy="0 0 0" />
                <geometry>
                    <mesh
                    filename="package://dvrk_model/meshes/instruments/420006/tool_wrist_sca_ee_link_2.STL" />
                </geometry>
                </collision>
            </link>
            <joint
                name="${prefix}jaw_2"
                type="revolute">
                <origin
                xyz="0 0 0"
                rpy="0 0 0" />
                <parent
                link="${prefix}tool_wrist_sca_shaft_link" />
                <child
                link="${prefix}tool_wrist_sca_ee_link_2" />
                <axis
                xyz="-1 0 0" />
                <limit
                lower="-1.5717"
                upper="1.5717"
                effort="0"
                velocity="0" />
            </joint>
        </xacro:if>


        <xacro:if value="${tool_name == 'SF826001'}">
            <link
                name="${prefix}tool_main_link">
                <inertial>
                <origin
                    xyz="0.027158 2.6368E-15 -0.11369"
                    rpy="0 0 0" />
                <mass
                    value="0.66229" />
                <inertia
                    ixx="0.001902"
                    ixy="2.1435E-18"
                    ixz="7.3606E-06"
                    iyy="0.0016701"
                    iyz="4.919E-19"
                    izz="0.00035117" />
                </inertial>
                <visual>
                <origin
                    xyz="0 0 0"
                    rpy="0 0 0" />
                <geometry>
                    <mesh
                    filename="package://dvrk_model/meshes/instruments/SF0826001/tool_main_link.STL" />
                </geometry>
                <material
                    name="">
                    <color
                    rgba="0.79216 0.81961 0.93333 1" />
                </material>
                </visual>
                <collision>
                <origin
                    xyz="0 0 0"
                    rpy="0 0 0" />
                <geometry>
                    <mesh
                    filename="package://dvrk_model/meshes/instruments/SF0826001/tool_main_link.STL" />
                </geometry>
                </collision>
            </link>
            <joint
                name="${prefix}outer_insertion"
                type="revolute">
                <origin
                xyz="0 0 0"
                rpy="0 0 0" />
                <parent
                link="${parent_link}" />
                <child
                link="${prefix}tool_main_link" />
                <axis
                xyz="0 0 1" />
                <limit
                lower="0"
                upper="0.2987"
                effort="0"
                velocity="0" />
            </joint>
            <link
                name="${prefix}tool_roll_link">
                <inertial>
                <origin
                    xyz="0.00131 2.3803E-08 -0.0016785"
                    rpy="0 0 0" />
                <mass
                    value="0.00013273" />
                <inertia
                    ixx="9.6885E-10"
                    ixy="2.8872E-14"
                    ixz="1.6022E-10"
                    iyy="7.4038E-10"
                    iyz="-9.9047E-16"
                    izz="1.3365E-09" />
                </inertial>
                <visual>
                <origin
                    xyz="0 0 0"
                    rpy="0 0 0" />
                <geometry>
                    <mesh
                    filename="package://dvrk_model/meshes/instruments/SF0826001/tool_roll_link.STL" />
                </geometry>
                <material
                    name="">
                    <color
                    rgba="0.79216 0.81961 0.93333 1" />
                </material>
                </visual>
                <collision>
                <origin
                    xyz="0 0 0"
                    rpy="0 0 0" />
                <geometry>
                    <mesh
                    filename="package://dvrk_model/meshes/instruments/SF0826001/tool_roll_link.STL" />
                </geometry>
                </collision>
            </link>
            <joint
                name="${prefix}outer_yaw"
                type="revolute">
                <origin
                xyz="0.05591 0 -0.53039"
                rpy="0 0 0" />
                <parent
                link="${prefix}tool_main_link" />
                <child
                link="${prefix}tool_roll_link" />
                <axis
                xyz="0 0 1" />
                <limit
                lower="-3.14"
                upper="3.14"
                effort="0"
                velocity="0" />
            </joint>
        </xacro:if>

    </xacro:macro>
</robot>